<?xml version="1.0" ?>
<robot name="robotic_arm">
    <link name="world" />
    <link name="base_link">
        
<inertial>
            <origin xyz="0.0 0.0 0.0" rpy="0.0 0.0 0.0" />
            <mass value="1" />
            <inertia ixx="0.001" ixy="0.0" ixz="0.0" iyy="0.001" iyz="0.0" izz="0.001" />
        </inertial>

        <visual>
            <origin xyz="0.0 0.0 0.062" rpy="0.0 0.0 0.0" />
            <geometry>
                <box size="0.1 0.1 0.1245" />
            </geometry>
            <material name="red">
                <color rgba="1.0 0.0 0.0 1.0" />
            </material>
        </visual>
        <collision>
            <origin xyz="0.0 0.0 0.062" rpy="0.0 0.0 0.0" />
            <geometry>
                <box size="0.1 0.1 0.124" />
            </geometry>
        </collision>
    </link>
    <link name="link_1">
        
<inertial>
            <origin xyz="0.0 0.0 0.0" rpy="0.0 0.0 0.0" />
            <mass value="0.01" />
            <inertia ixx="0.001" ixy="0.0" ixz="0.0" iyy="0.001" iyz="0.0" izz="0.001" />
        </inertial>

        <visual>
            <origin xyz="0.0 0.0 0.0326" rpy="0.0 0.0 0.0" />
            <geometry>
                <box size="0.03 0.03 0.0652" />
            </geometry>
            <material name="blue">
                <color rgba="0.0 0.0 1.0 1.0" />
            </material>
        </visual>
        <collision>
            <origin xyz="0.0 0.0 0.0326" rpy="0.0 0.0 0.0" />
            <geometry>
                <box size="0.03 0.03 0.0652" />
            </geometry>
        </collision>
    </link>
    <link name="link_2">
        
<inertial>
            <origin xyz="0.0 0.0 0.0" rpy="0.0 0.0 0.0" />
            <mass value="0.01" />
            <inertia ixx="0.001" ixy="0.0" ixz="0.0" iyy="0.001" iyz="0.0" izz="0.001" />
        </inertial>

        <visual>
            <origin xyz="0.0 0.0 0.07225" rpy="0.0 0.0 0.0" />
            <geometry>
                <box size="0.03 0.03 0.1445" />
            </geometry>
            <material name="green">
                <color rgba="0.0 1.0 0.0 1.0" />
            </material>
        </visual>
        <collision>
            <origin xyz="0.0 0.0 0.07225" rpy="0.0 0.0 0.0" />
            <geometry>
                <box size="0.03 0.03 0.1445" />
            </geometry>
        </collision>
    </link>
    <link name="link_3">
        
<inertial>
            <origin xyz="0.0 0.0 0.0" rpy="0.0 0.0 0.0" />
            <mass value="0.01" />
            <inertia ixx="0.001" ixy="0.0" ixz="0.0" iyy="0.001" iyz="0.0" izz="0.001" />
        </inertial>

        <visual>
            <origin xyz="0.0 0.0 0.06725" rpy="0.0 0.0 0.0" />
            <geometry>
                <box size="0.03 0.03 0.1345" />
            </geometry>
            <material name="blue">
                <color rgba="1.0 0.0 0.0 1.0" />
            </material>
        </visual>
        <collision>
            <origin xyz="0.0 0.0 0.06725" rpy="0.0 0.0 0.0" />
            <geometry>
                <box size="0.03 0.03 0.1345" />
            </geometry>
        </collision>
    </link>
    <link name="link_4">
        
<inertial>
            <origin xyz="0.0 0.0 0.0" rpy="0.0 0.0 0.0" />
            <mass value="0.01" />
            <inertia ixx="0.001" ixy="0.0" ixz="0.0" iyy="0.001" iyz="0.0" izz="0.001" />
        </inertial>

        <visual>
            <origin xyz="0.0 0.0 0.0326" rpy="0.0 0.0 0.0" />
            <geometry>
                <box size="0.03 0.03 0.0652" />
            </geometry>
            <material name="green">
                <color rgba="0.0 0.1 0.0 1.0" />
            </material>
        </visual>
        <collision>
            <origin xyz="0.0 0.0 0.0326" rpy="0.0 0.0 0.0" />
            <geometry>
                <box size="0.03 0.03 0.0652" />
            </geometry>
        </collision>
    </link>
    <link name="link_5">
        
<inertial>
            <origin xyz="0.0 0.0 0.0" rpy="0.0 0.0 0.0" />
            <mass value="0.01" />
            <inertia ixx="0.001" ixy="0.0" ixz="0.0" iyy="0.001" iyz="0.0" izz="0.001" />
        </inertial>

        <visual>
            <origin xyz="0.0 0.0 0.05035" rpy="0.0 0.0 0.0" />
            <geometry>
                <box size="0.03 0.03 0.1007" />
            </geometry>
            <material name="blue">
                <color rgba="0.0 0.0 1.0 1.0" />
            </material>
        </visual>
        <collision>
            <origin xyz="0.0 0.0 0.05035" rpy="0.0 0.0 0.0" />
            <geometry>
                <box size="0.03 0.03 0.1007" />
            </geometry>
        </collision>
    </link>
    <link name="link_6">
        
<inertial>
            <origin xyz="0.0 0.0 0.0" rpy="0.0 0.0 0.0" />
            <mass value="0.01" />
            <inertia ixx="0.001" ixy="0.0" ixz="0.0" iyy="0.001" iyz="0.0" izz="0.001" />
        </inertial>

        <visual>
            <origin xyz="0.0 0.0 0.005" rpy="0.0 0.0 0.0" />
            <geometry>
                <box size="0.03 0.03 0.01" />
            </geometry>
            <material name="green">
                <color rgba="0.0 1.0 0.0 1.0" />
            </material>
        </visual>
        <collision>
            <origin xyz="0.0 0.0 0.005" rpy="0.0 0.0 0.0" />
            <geometry>
                <box size="0.03 0.03 0.01" />
            </geometry>
        </collision>
    </link>
    <link name="depth_camera_1">
        
<inertial>
            <origin xyz="0.0 0.0 0.0" rpy="0.0 0.0 0.0" />
            <mass value="0.001" />
            <inertia ixx="0.001" ixy="0.0" ixz="0.0" iyy="0.001" iyz="0.0" izz="0.001" />
        </inertial>

        <visual>
            <origin xyz="0.0 0.0 0.0" rpy="1.57 0.0 1.57" />
            <geometry>
                <box size="0.02 0.02 0.05" />
            </geometry>
            <material name="red">
                <color rgba="1.0 0.0 0.0 1.0" />
            </material>
        </visual>
        <collision>
            <origin xyz="0.0 0.0 0.0" rpy="1.57 0.0 1.57" />
            <geometry>
                <box size="0.02 0.02 0.05" />
            </geometry>
        </collision>
    </link>

    <link name="depth_camera" />
    <link name="camera_link_optical" />
    <joint name="world_joint" type="fixed">
        <parent link="world" />
        <child link="base_link" />
        <origin xyz="0.0 0.0 0.0" rpy="0.0 0.0 0.0" />
    </joint>
    <joint name="rev_1" type="revolute">
        <parent link="base_link" />
        <child link="link_1" />
        <axis xyz="0 0 1" />
        <limit lower="-2.269" upper="2.269" velocity="50.0" effort="1000.0" />
        <origin xyz="0 0 0.124" rpy="0 0 0" />
    </joint>
    <joint name="rev_2" type="revolute">
        <parent link="link_1" />
        <child link="link_2" />
        <axis xyz="1 0 0" />
        <limit lower="-2.269" upper="2.269" velocity="50.0" effort="1000.0" />
        <origin xyz="0 0 0.0652" rpy="0 0 0" />
    </joint>
    <joint name="rev_3" type="revolute">
        <parent link="link_2" />
        <child link="link_3" />
        <axis xyz="1 0 0" />
        <limit lower="-2.269" upper="2.269" velocity="50.0" effort="1000.0" />
        <origin xyz="0 0 0.1445" rpy="0 0 0" />
    </joint>
    <joint name="rev_4" type="revolute">
        <parent link="link_3" />
        <child link="link_4" />
        <axis xyz="0 0 1" />
        <limit lower="-2.269" upper="2.269" velocity="50.0" effort="1000.0" />
        <origin xyz="0 0 0.1345" rpy="0 0 0" />
    </joint>
    <joint name="rev_5" type="revolute">
        <parent link="link_4" />
        <child link="link_5" />
        <axis xyz="1 0 0" />
        <limit lower="-2.269" upper="2.269" velocity="50.0" effort="1000.0" />
        <origin xyz="0 0 0.0652" rpy="0 0 0" />
    </joint>
    <joint name="rev_6" type="revolute">
        <parent link="link_5" />
        <child link="link_6" />
        <axis xyz="0 0 1" />
        <limit lower="-2.269" upper="2.269" velocity="50.0" effort="1000.0" />
        <origin xyz="0 0 0.1007" rpy="0 0 0" />
    </joint>
    <joint name="rigit_7" type="fixed">
        <parent link="link_5" />
        <child link="depth_camera_1" />
        <origin xyz="0.0 -0.025 0.090" rpy="0.0 0.0 0.0" />
    </joint>
    <joint name="joint_camera" type="fixed">
        <origin rpy="0 -1.57 0" xyz="0 0 0" />
        <parent link="depth_camera_1" />
        <child link="depth_camera" />
    </joint>
    <joint name="camera_optical_joint" type="fixed">
        <!-- these values have to be these values otherwise the gazebo camera
        image won't be aligned properly with the frame it is supposedly
        originating from -->
        <origin xyz="0 0 0" rpy="-1.57079632679 0 -1.57079632679" />
        <parent link="depth_camera" />
        <child link="camera_link_optical" />
    </joint>
    
<transmission name="trans_rev_1">
        <type>transmission_interface/SimpleTransmission</type>
        <joint name="rev_1">
            <hardwareInterface>hardware_interface/EffortJointInterface</hardwareInterface>
        </joint>
        <actuator name="rev_1_motor">
            <hardwareInterface>hardware_interface/EffortJointInterface</hardwareInterface>
            <mechanicalReduction>1</mechanicalReduction>
        </actuator>
    </transmission>
    <transmission name="trans_rev_2">
        <type>transmission_interface/SimpleTransmission</type>
        <joint name="rev_2">
            <hardwareInterface>hardware_interface/EffortJointInterface</hardwareInterface>
        </joint>
        <actuator name="rev_2_motor">
            <hardwareInterface>hardware_interface/EffortJointInterface</hardwareInterface>
            <mechanicalReduction>1</mechanicalReduction>
        </actuator>
    </transmission>
    <transmission name="trans_rev_3">
        <type>transmission_interface/SimpleTransmission</type>
        <joint name="rev_3">
            <hardwareInterface>hardware_interface/EffortJointInterface</hardwareInterface>
        </joint>
        <actuator name="rev_3_motor">
            <hardwareInterface>hardware_interface/EffortJointInterface</hardwareInterface>
            <mechanicalReduction>1</mechanicalReduction>
        </actuator>
    </transmission>
    <transmission name="trans_rev_4">
        <type>transmission_interface/SimpleTransmission</type>
        <joint name="rev_4">
            <hardwareInterface>hardware_interface/EffortJointInterface</hardwareInterface>
        </joint>
        <actuator name="rev_4_motor">
            <hardwareInterface>hardware_interface/EffortJointInterface</hardwareInterface>
            <mechanicalReduction>1</mechanicalReduction>
        </actuator>
    </transmission>
    <transmission name="trans_rev_5">
        <type>transmission_interface/SimpleTransmission</type>
        <joint name="rev_5">
            <hardwareInterface>hardware_interface/EffortJointInterface</hardwareInterface>
        </joint>
        <actuator name="rev_5_motor">
            <hardwareInterface>hardware_interface/EffortJointInterface</hardwareInterface>
            <mechanicalReduction>1</mechanicalReduction>
        </actuator>
    </transmission>
    <transmission name="trans_rev_6">
        <type>transmission_interface/SimpleTransmission</type>
        <joint name="rev_6">
            <hardwareInterface>hardware_interface/EffortJointInterface</hardwareInterface>
        </joint>
        <actuator name="rev_6_motor">
            <hardwareInterface>hardware_interface/EffortJointInterface</hardwareInterface>
            <mechanicalReduction>1</mechanicalReduction>
        </actuator>
    </transmission>
    <gazebo>
        <plugin name="gazebo_ros_control" filename="libgazebo_ros_control.so">
            <robotNamespace>/</robotNamespace>
        </plugin>
    </gazebo>

    <gazebo reference="base_link"> 
        <material>Gazebo/Red</material> 
    </gazebo> 

    <gazebo reference="link_1"> 
        <material>Gazebo/Blue</material> 
    </gazebo> 

    <gazebo reference="link_2"> 
        <material>Gazebo/Green</material> 
    </gazebo> 

    <gazebo reference="link_3"> 
        <material>Gazebo/Blue</material> 
    </gazebo> 

    <gazebo reference="link_4"> 
        <material>Gazebo/Green</material> 
    </gazebo> 

    <gazebo reference="link_5"> 
        <material>Gazebo/Blue</material> 
    </gazebo> 

    <gazebo reference="link_6"> 
        <material>Gazebo/Green</material> 
    </gazebo> 

    <gazebo reference="depth_camera_1"> 
        <material>Gazebo/Red</material> 
    </gazebo> 

    <gazebo reference="depth_camera">
        <sensor name="depth_camera_camera" type="depth">
            <update_rate>20</update_rate>
            <camera>
                <horizontal_fov>1.047198</horizontal_fov>
                <image>
                    <width>500</width>
                    <height>500</height>
                    <format>R8G8B8</format>
                </image>
                <clip>
                    <near>0.05</near>
                    <far>3</far>
                </clip>
            </camera>
            <plugin name="depth_camera_controller" filename="libgazebo_ros_openni_kinect.so">
                <baseline>0.2</baseline>
                <alwaysOn>true</alwaysOn>
                <updateRate>1.0</updateRate>
                <cameraName>depth_camera_ir</cameraName>
                <imageTopicName>/depth_camera/color/image_raw</imageTopicName>
                <cameraInfoTopicName>/depth_camera/color/camera_info</cameraInfoTopicName>
                <depthImageTopicName>/depth_camera/depth/image_raw</depthImageTopicName>
                <depthImageInfoTopicName>/depth_camera/depth/camera_info</depthImageInfoTopicName>
                <pointCloudTopicName>/depth_camera/depth/points</pointCloudTopicName>
                <frameName>camera_link_optical</frameName>
                <pointCloudCutoff>0.05</pointCloudCutoff>
                <pointCloudCutoffMax>3.0</pointCloudCutoffMax>
                <distortionK1>0.00000001</distortionK1>
                <distortionK2>0.00000001</distortionK2>
                <distortionK3>0.00000001</distortionK3>
                <distortionT1>0.00000001</distortionT1>
                <distortionT2>0.00000001</distortionT2>
                <CxPrime>0</CxPrime>
                <Cx>0</Cx>
                <Cy>0</Cy>
                <focalLength>0</focalLength>
                <hackBaseline>0</hackBaseline>
            </plugin>
        </sensor>
    </gazebo>
</robot>