<?xml version="1.0" ?>
<robot name="mm_bot">
    <link name="base_footprint">
        
<inertial>
            <origin xyz="0.0 0.0 0.0" rpy="0.0 0.0 0.0" />
            <mass value="10.0" />
            <inertia ixx="0.1" ixy="0.0" ixz="0.0" iyy="0.1" iyz="0.0" izz="0.1" />
        </inertial>

        <visual>
            <origin xyz="0.0 0.0 0.2" rpy="0.0 0.0 0.0" />
            <geometry>
                <box size="0.6 0.4 0.2" />
            </geometry>
            <material name="green">
                <color rgba="0.0 1.0 0.0 1.0" />
            </material>
        </visual>
        <collision>
            <origin xyz="0.0 0.0 0.2" rpy="0.0 0.0 0.0" />
            <geometry>
                <box size="0.6 0.4 0.2" />
            </geometry>
        </collision>
    </link>
    <link name="left_wheel">
        
<inertial>
            <origin xyz="0.0 0.0 0.0" rpy="0.0 0.0 0.0" />
            <mass value="0.1" />
            <inertia ixx="0.1" ixy="0.0" ixz="0.0" iyy="0.1" iyz="0.0" izz="0.1" />
        </inertial>

        <visual>
            <origin xyz="0.0 0.0 0.0" rpy="0.0 0.0 0.0" />
            <geometry>
                <cylinder radius="0.1" length="0.05" />
            </geometry>
            <material name="gray">
                <color rgba="0.5 0.5 0.5 1.0" />
            </material>
        </visual>
        <collision>
            <origin xyz="0.0 0.0 0.0" rpy="0.0 0.0 0.0" />
            <geometry>
                <cylinder radius="0.1" length="0.05" />
            </geometry>
            <surface>
                <friction>
                  <ode>
                    <mu>0</mu>
                    <mu2>0</mu2>
                    <slip1>1.0</slip1>
                    <slip2>1.0</slip2>
                  </ode>
                </friction>
              </surface>
              <contact_coefficients mu="1" kp="1e+13" kd="1.0"/>
        </collision>
    </link>
    <link name="right_wheel">
        
<inertial>
            <origin xyz="0.0 0.0 0.0" rpy="0.0 0.0 0.0" />
            <mass value="0.1" />
            <inertia ixx="0.1" ixy="0.0" ixz="0.0" iyy="0.1" iyz="0.0" izz="0.1" />
        </inertial>

        <visual>
            <origin xyz="0.0 0.0 0.0" rpy="0.0 0.0 0.0" />
            <geometry>
                <cylinder radius="0.1" length="0.05" />
            </geometry>
            <material name="blue">
                <color rgba="0.0 0.0 1.0 1.0" />
            </material>
        </visual>
        <collision>
            <origin xyz="0.0 0.0 0.0" rpy="0.0 0.0 0.0" />
            <geometry>
                <cylinder radius="0.1" length="0.05" />
            </geometry>
            <surface>
                <friction>
                  <ode>
                    <mu>0</mu>
                    <mu2>0</mu2>
                    <slip1>1.0</slip1>
                    <slip2>1.0</slip2>
                  </ode>
                </friction>
              </surface>
              <contact_coefficients mu="1" kp="1e+13" kd="1.0"/>
        </collision>
    </link>
    <link name="caster_left_1">
        
<inertial>
            <origin xyz="0.0 0.0 0.0" rpy="0.0 0.0 0.0" />
            <mass value="0.01" />
            <inertia ixx="0.1" ixy="0.0" ixz="0.0" iyy="0.1" iyz="0.0" izz="0.1" />
        </inertial>

        <visual>
            <origin xyz="0.0 0.0 0.0" rpy="0.0 0.0 0.0" />
            <geometry>
                <box size="0.1 0.1 0.1" />
            </geometry>
            <material name="red">
                <color rgba="1.0 0.0 0.0 1.0" />
            </material>
        </visual>
        <collision>
            <origin xyz="0.0 0.0 0.0" rpy="0.0 0.0 0.0" />
            <geometry>
                <box size="0.1 0.1 0.1" />
            </geometry>
        </collision>
    </link>
    <link name="caster_left_2">
        
<inertial>
            <origin xyz="0.0 0.0 0.0" rpy="0.0 0.0 0.0" />
            <mass value="0.01" />
            <inertia ixx="0.1" ixy="0.0" ixz="0.0" iyy="0.1" iyz="0.0" izz="0.1" />
        </inertial>

        <visual>
            <origin xyz="0.0 0.0 0.0" rpy="0.0 0.0 0.0" />
            <geometry>
                <cylinder radius="0.05" length="0.02" />
            </geometry>
            <material name="blue">
                <color rgba="0.0 0.0 1.0 1.0" />
            </material>
        </visual>
        <collision>
            <origin xyz="0.0 0.0 0.0" rpy="0.0 0.0 0.0" />
            <geometry>
                <cylinder radius="0.05" length="0.02" />
            </geometry>
            <surface>
                <friction>
                  <ode>
                    <mu>0</mu>
                    <mu2>0</mu2>
                    <slip1>1.0</slip1>
                    <slip2>1.0</slip2>
                  </ode>
                </friction>
              </surface>
        </collision>
    </link>
    <link name="caster_right_1">
        
<inertial>
            <origin xyz="0.0 0.0 0.0" rpy="0.0 0.0 0.0" />
            <mass value="0.1" />
            <inertia ixx="0.1" ixy="0.0" ixz="0.0" iyy="0.1" iyz="0.0" izz="0.1" />
        </inertial>

        <visual>
            <origin xyz="0.0 0.0 0.0" rpy="0.0 0.0 0.0" />
            <geometry>
                <box size="0.1 0.1 0.1" />
            </geometry>
            <material name="red">
                <color rgba="1.0 0.0 0.0 1.0" />
            </material>
        </visual>
        <collision>
            <origin xyz="0.0 0.0 0.0" rpy="0.0 0.0 0.0" />
            <geometry>
                <box size="0.1 0.1 0.1" />
            </geometry>
        </collision>
    </link>
    <link name="caster_right_2">
        
<inertial>
            <origin xyz="0.0 0.0 0.0" rpy="0.0 0.0 0.0" />
            <mass value="0.1" />
            <inertia ixx="0.1" ixy="0.0" ixz="0.0" iyy="0.1" iyz="0.0" izz="0.1" />
        </inertial>

        <visual>
            <origin xyz="0.0 0.0 0.0" rpy="0.0 0.0 0.0" />
            <geometry>
                <cylinder radius="0.05" length="0.02" />
            </geometry>
            <material name="blue">
                <color rgba="0.0 0.0 1.0 1.0" />
            </material>
        </visual>
        <collision>
            <origin xyz="0.0 0.0 0.0" rpy="0.0 0.0 0.0" />
            <geometry>
                <cylinder radius="0.05" length="0.02" />
            </geometry>
            <surface>
                <friction>
                  <ode>
                    <mu>0</mu>
                    <mu2>0</mu2>
                    <slip1>1.0</slip1>
                    <slip2>1.0</slip2>
                  </ode>
                </friction>
              </surface>
        </collision>
    </link>
    <link name="laser_link">
        
<inertial>
            <origin xyz="0.0 0.0 0.0" rpy="0.0 0.0 0.0" />
            <mass value="0.1" />
            <inertia ixx="0.1" ixy="0.0" ixz="0.0" iyy="0.1" iyz="0.0" izz="0.1" />
        </inertial>

        <visual>
            <origin xyz="0.0 0.0 0.0" rpy="0.0 0.0 0.0" />
            <geometry>
                <cylinder radius="0.05" length="0.08" />
            </geometry>
            <material name="red">
                <color rgba="1.0 0.0 0.0 1.0" />
            </material>
        </visual>
        <collision>
            <origin xyz="0.0 0.0 0.0" rpy="0.0 0.0 0.0" />
            <geometry>
                <cylinder radius="0.05" length="0.08" />
            </geometry>
        </collision>
    </link>
    <!-- End -->
    <!-- Mobile Joints -->
    <joint name="left_wheel_joint" type="continuous">
        <parent link="base_footprint" />
        <child link="left_wheel" />
        <axis xyz="0 0 -1" />
        <origin xyz="0 0.225 0.1" rpy="1.57079632679 0 0" />
    </joint>
    <joint name="right_wheel_joint" type="continuous">
        <parent link="base_footprint" />
        <child link="right_wheel" />
        <axis xyz="0 0 -1" />
        <origin xyz="0 -0.225 0.1" rpy="1.57079632679 0 0" />
    </joint>
    <joint name="caster_left_1_joint" type="continuous">
        <parent link="base_footprint" />
        <child link="caster_left_1" />
        <axis xyz="0 0 1" />
        <origin xyz="-0.25 0 0.15" rpy="0 0 0" />
    </joint>
    <joint name="caster_left_2_joint" type="continuous">
        <parent link="caster_left_1" />
        <child link="caster_left_2" />
        <axis xyz="0 0 1" />
        <origin xyz="0.05 0.0 -0.1" rpy="1.5708 0 0" />
    </joint>
    <joint name="caster_right_1_joint" type="continuous">
        <parent link="base_footprint" />
        <child link="caster_right_1" />
        <axis xyz="0 0 1" />
        <origin xyz="0.25 0 0.15" rpy="0 0 0" />
    </joint>
    <joint name="caster_right_2_joint" type="continuous">
        <parent link="caster_right_1" />
        <child link="caster_right_2" />
        <axis xyz="0 0 1" />
        <origin xyz="0.05 0.0 -0.1" rpy="1.5708 0 0" />
    </joint>
    <joint name="laser_link_joint" type="fixed">
        <parent link="base_footprint" />
        <child link="laser_link" />
        <origin xyz="0.35 0.0 0.15" rpy="0 0 0" />
    </joint>
    <!-- End -->

    <!-- Gazebo Colors -->
    <gazebo reference="base_footprint">
        <material>Gazebo/Green</material>
    </gazebo>
    <gazebo reference="left_wheel">
        <material>Gazebo/Blue</material>
    </gazebo>
    <gazebo reference="right_wheel">
        <material>Gazebo/Blue</material>
    </gazebo>
    <gazebo reference="caster_left_1">
        <material>Gazebo/Red</material>
    </gazebo>
    <gazebo reference="caster_right_1">
        <material>Gazebo/Red</material>
    </gazebo>
    <gazebo reference="caster_left_2">
        <material>Gazebo/Blue</material>
    </gazebo>
    <gazebo reference="caster_right_2">
        <material>Gazebo/Blue</material>
    </gazebo>
    <gazebo reference="laser_link">
        <material>Gazebo/Red</material>
    </gazebo>
 
    <!-- Gazebo Colors -->
    <!-- hokuyo -->
    <gazebo reference="laser_link">
        <sensor type="ray" name="head_hokuyo_sensor">
            <pose>0 0 0 0 0 0</pose>
            <visualize>true</visualize>
            <update_rate>40</update_rate>
            <ray>
                <scan>
                    <horizontal>
                        <samples>720</samples>
                        <resolution>1</resolution>
                        <min_angle>-1.57</min_angle>
                        <max_angle>1.57</max_angle>
                    </horizontal>
                </scan>
                <range>
                    <min>0.10</min>
                    <max>20.0</max>
                    <resolution>0.01</resolution>
                </range>
                <noise>
                    <type>gaussian</type>
                    <!-- Noise parameters based on published spec for Hokuyo laser
                achieving "+-30mm" accuracy at range < 10m.  A mean of 0.0m and
                stddev of 0.01m will put 99.7% of samples within 0.03m of the true
                reading. -->
                    <mean>0.0</mean>
                    <stddev>0.01</stddev>
                </noise>
            </ray>
            <plugin name="gazebo_ros_head_hokuyo_controller" filename="libgazebo_ros_laser.so">
                <topicName>mm_bot/scan</topicName>
                <frameName>laser_link</frameName>
            </plugin>
        </sensor>
    </gazebo>
    <!-- diffrential drive plugin -->
    <gazebo>
        <plugin name="differential_drive_controller" filename="libgazebo_ros_diff_drive.so">
            <leftJoint>left_wheel_joint</leftJoint>
            <rightJoint>right_wheel_joint</rightJoint>
            <legacyMode>false</legacyMode>
            <robotBaseFrame>base_footprint</robotBaseFrame>
            <wheelSeparation>0.45</wheelSeparation>
            <wheelDiameter>0.2</wheelDiameter>
            <publishWheelJointState>true</publishWheelJointState>
        </plugin>
    </gazebo>
    <!-- diffrential drive plugin -->
    <gazebo>
        <plugin name="gazebo_ros_control" filename="libgazebo_ros_control.so">
            <robotNamespace>/</robotNamespace>
        </plugin>
    </gazebo>
</robot>